2019-09-11 17:29:56,918 ERROR: Exception on /edit_profile [POST] [in /home/elama/main_projects/test_flask_blog/test_flask_blog/venv/lib/python3.6/site-packages/flask/app.py:1891]
Traceback (most recent call last):
  File "/home/elama/main_projects/test_flask_blog/test_flask_blog/venv/lib/python3.6/site-packages/sqlalchemy/engine/base.py", line 1249, in _execute_context
    cursor, statement, parameters, context
  File "/home/elama/main_projects/test_flask_blog/test_flask_blog/venv/lib/python3.6/site-packages/sqlalchemy/engine/default.py", line 552, in do_execute
    cursor.execute(statement, parameters)
psycopg2.errors.UniqueViolation: duplicate key value violates unique constraint "ix_user_username"
DETAIL:  Key (username)=(susan) already exists.


The above exception was the direct cause of the following exception:

Traceback (most recent call last):
  File "/home/elama/main_projects/test_flask_blog/test_flask_blog/venv/lib/python3.6/site-packages/flask/app.py", line 2446, in wsgi_app
    response = self.full_dispatch_request()
  File "/home/elama/main_projects/test_flask_blog/test_flask_blog/venv/lib/python3.6/site-packages/flask/app.py", line 1951, in full_dispatch_request
    rv = self.handle_user_exception(e)
  File "/home/elama/main_projects/test_flask_blog/test_flask_blog/venv/lib/python3.6/site-packages/flask/app.py", line 1820, in handle_user_exception
    reraise(exc_type, exc_value, tb)
  File "/home/elama/main_projects/test_flask_blog/test_flask_blog/venv/lib/python3.6/site-packages/flask/_compat.py", line 39, in reraise
    raise value
  File "/home/elama/main_projects/test_flask_blog/test_flask_blog/venv/lib/python3.6/site-packages/flask/app.py", line 1949, in full_dispatch_request
    rv = self.dispatch_request()
  File "/home/elama/main_projects/test_flask_blog/test_flask_blog/venv/lib/python3.6/site-packages/flask/app.py", line 1935, in dispatch_request
    return self.view_functions[rule.endpoint](**req.view_args)
  File "/home/elama/main_projects/test_flask_blog/test_flask_blog/venv/lib/python3.6/site-packages/flask_login/utils.py", line 261, in decorated_view
    return func(*args, **kwargs)
  File "/home/elama/main_projects/test_flask_blog/test_flask_blog/app/views.py", line 109, in edit_profile
    db.session.commit()
  File "/home/elama/main_projects/test_flask_blog/test_flask_blog/venv/lib/python3.6/site-packages/sqlalchemy/orm/scoping.py", line 162, in do
    return getattr(self.registry(), name)(*args, **kwargs)
  File "/home/elama/main_projects/test_flask_blog/test_flask_blog/venv/lib/python3.6/site-packages/sqlalchemy/orm/session.py", line 1027, in commit
    self.transaction.commit()
  File "/home/elama/main_projects/test_flask_blog/test_flask_blog/venv/lib/python3.6/site-packages/sqlalchemy/orm/session.py", line 494, in commit
    self._prepare_impl()
  File "/home/elama/main_projects/test_flask_blog/test_flask_blog/venv/lib/python3.6/site-packages/sqlalchemy/orm/session.py", line 473, in _prepare_impl
    self.session.flush()
  File "/home/elama/main_projects/test_flask_blog/test_flask_blog/venv/lib/python3.6/site-packages/sqlalchemy/orm/session.py", line 2459, in flush
    self._flush(objects)
  File "/home/elama/main_projects/test_flask_blog/test_flask_blog/venv/lib/python3.6/site-packages/sqlalchemy/orm/session.py", line 2597, in _flush
    transaction.rollback(_capture_exception=True)
  File "/home/elama/main_projects/test_flask_blog/test_flask_blog/venv/lib/python3.6/site-packages/sqlalchemy/util/langhelpers.py", line 68, in __exit__
    compat.reraise(exc_type, exc_value, exc_tb)
  File "/home/elama/main_projects/test_flask_blog/test_flask_blog/venv/lib/python3.6/site-packages/sqlalchemy/util/compat.py", line 153, in reraise
    raise value
  File "/home/elama/main_projects/test_flask_blog/test_flask_blog/venv/lib/python3.6/site-packages/sqlalchemy/orm/session.py", line 2557, in _flush
    flush_context.execute()
  File "/home/elama/main_projects/test_flask_blog/test_flask_blog/venv/lib/python3.6/site-packages/sqlalchemy/orm/unitofwork.py", line 422, in execute
    rec.execute(self)
  File "/home/elama/main_projects/test_flask_blog/test_flask_blog/venv/lib/python3.6/site-packages/sqlalchemy/orm/unitofwork.py", line 589, in execute
    uow,
  File "/home/elama/main_projects/test_flask_blog/test_flask_blog/venv/lib/python3.6/site-packages/sqlalchemy/orm/persistence.py", line 236, in save_obj
    update,
  File "/home/elama/main_projects/test_flask_blog/test_flask_blog/venv/lib/python3.6/site-packages/sqlalchemy/orm/persistence.py", line 996, in _emit_update_statements
    statement, multiparams
  File "/home/elama/main_projects/test_flask_blog/test_flask_blog/venv/lib/python3.6/site-packages/sqlalchemy/engine/base.py", line 988, in execute
    return meth(self, multiparams, params)
  File "/home/elama/main_projects/test_flask_blog/test_flask_blog/venv/lib/python3.6/site-packages/sqlalchemy/sql/elements.py", line 287, in _execute_on_connection
    return connection._execute_clauseelement(self, multiparams, params)
  File "/home/elama/main_projects/test_flask_blog/test_flask_blog/venv/lib/python3.6/site-packages/sqlalchemy/engine/base.py", line 1107, in _execute_clauseelement
    distilled_params,
  File "/home/elama/main_projects/test_flask_blog/test_flask_blog/venv/lib/python3.6/site-packages/sqlalchemy/engine/base.py", line 1253, in _execute_context
    e, statement, parameters, cursor, context
  File "/home/elama/main_projects/test_flask_blog/test_flask_blog/venv/lib/python3.6/site-packages/sqlalchemy/engine/base.py", line 1473, in _handle_dbapi_exception
    util.raise_from_cause(sqlalchemy_exception, exc_info)
  File "/home/elama/main_projects/test_flask_blog/test_flask_blog/venv/lib/python3.6/site-packages/sqlalchemy/util/compat.py", line 398, in raise_from_cause
    reraise(type(exception), exception, tb=exc_tb, cause=cause)
  File "/home/elama/main_projects/test_flask_blog/test_flask_blog/venv/lib/python3.6/site-packages/sqlalchemy/util/compat.py", line 152, in reraise
    raise value.with_traceback(tb)
  File "/home/elama/main_projects/test_flask_blog/test_flask_blog/venv/lib/python3.6/site-packages/sqlalchemy/engine/base.py", line 1249, in _execute_context
    cursor, statement, parameters, context
  File "/home/elama/main_projects/test_flask_blog/test_flask_blog/venv/lib/python3.6/site-packages/sqlalchemy/engine/default.py", line 552, in do_execute
    cursor.execute(statement, parameters)
sqlalchemy.exc.IntegrityError: (psycopg2.errors.UniqueViolation) duplicate key value violates unique constraint "ix_user_username"
DETAIL:  Key (username)=(susan) already exists.

[SQL: UPDATE "user" SET first_name=%(first_name)s, last_name=%(last_name)s, username=%(username)s, about_me=%(about_me)s WHERE "user".id = %(user_id)s]
[parameters: {'first_name': 'Екатерина', 'last_name': 'Фролова', 'username': 'susan', 'about_me': 'я программист!', 'user_id': 4}]
(Background on this error at: http://sqlalche.me/e/gkpj)
2019-09-11 17:30:02,738 INFO: Microblog startup [in /home/elama/main_projects/test_flask_blog/test_flask_blog/app/__init__.py:48]
2019-09-11 17:50:04,786 INFO: Microblog startup [in /home/elama/main_projects/test_flask_blog/test_flask_blog/app/__init__.py:48]
2019-09-11 17:50:41,608 INFO: Microblog startup [in /home/elama/main_projects/test_flask_blog/test_flask_blog/app/__init__.py:48]
2019-09-11 17:50:52,781 INFO: Microblog startup [in /home/elama/main_projects/test_flask_blog/test_flask_blog/app/__init__.py:48]
2019-09-12 12:41:57,154 INFO: Microblog startup [in /home/elama/main_projects/test_flask_blog/test_flask_blog/app/__init__.py:48]
2019-09-12 12:42:00,950 INFO: Microblog startup [in /home/elama/main_projects/test_flask_blog/test_flask_blog/app/__init__.py:48]
2019-09-12 12:47:28,327 INFO: Microblog startup [in /home/elama/main_projects/test_flask_blog/test_flask_blog/app/__init__.py:48]
2019-09-12 12:49:09,961 INFO: Microblog startup [in /home/elama/main_projects/test_flask_blog/test_flask_blog/app/__init__.py:48]
2019-09-12 12:49:14,707 INFO: Microblog startup [in /home/elama/main_projects/test_flask_blog/test_flask_blog/app/__init__.py:48]
2019-09-12 12:49:17,469 INFO: Microblog startup [in /home/elama/main_projects/test_flask_blog/test_flask_blog/app/__init__.py:48]
2019-09-12 12:50:24,485 INFO: Microblog startup [in /home/elama/main_projects/test_flask_blog/test_flask_blog/app/__init__.py:48]
2019-09-12 12:54:05,635 INFO: Microblog startup [in /home/elama/main_projects/test_flask_blog/test_flask_blog/app/__init__.py:48]
2019-09-12 13:00:45,546 INFO: Microblog startup [in /home/elama/main_projects/test_flask_blog/test_flask_blog/app/__init__.py:48]
2019-09-12 13:05:10,599 INFO: Microblog startup [in /home/elama/main_projects/test_flask_blog/test_flask_blog/app/__init__.py:48]
2019-09-12 13:05:11,024 INFO: Microblog startup [in /home/elama/main_projects/test_flask_blog/test_flask_blog/app/__init__.py:48]
2019-09-12 13:05:16,603 INFO: Microblog startup [in /home/elama/main_projects/test_flask_blog/test_flask_blog/app/__init__.py:48]
2019-09-12 13:07:53,207 INFO: Microblog startup [in /home/elama/main_projects/test_flask_blog/test_flask_blog/app/__init__.py:48]
2019-09-12 13:08:59,645 INFO: Microblog startup [in /home/elama/main_projects/test_flask_blog/test_flask_blog/app/__init__.py:48]
2019-09-12 13:10:37,488 INFO: Microblog startup [in /home/elama/main_projects/test_flask_blog/test_flask_blog/app/__init__.py:48]
2019-09-12 13:15:43,151 INFO: Microblog startup [in /home/elama/main_projects/test_flask_blog/test_flask_blog/app/__init__.py:48]
2019-09-12 13:16:04,941 INFO: Microblog startup [in /home/elama/main_projects/test_flask_blog/test_flask_blog/app/__init__.py:48]
2019-09-12 13:30:07,010 INFO: Microblog startup [in /home/elama/main_projects/test_flask_blog/test_flask_blog/app/__init__.py:48]
2019-09-12 13:30:21,704 INFO: Microblog startup [in /home/elama/main_projects/test_flask_blog/test_flask_blog/app/__init__.py:48]
2019-09-12 13:32:53,178 INFO: Microblog startup [in /home/elama/main_projects/test_flask_blog/test_flask_blog/app/__init__.py:48]
